<?xml version="1.0" ?>
<robot name="bbot_new" xmlns:xacro="http://www.ros.org/wiki/xacro">

<xacro:include filename="$(find bbot_new_description)/urdf/materials.xacro" />
<xacro:include filename="$(find bbot_new_description)/urdf/bbot_new.trans" />
<xacro:include filename="$(find bbot_new_description)/urdf/bbot_new.gazebo" />
<xacro:include filename="$(find bbot_new_description)/urdf/bbot_diff_drive_plugin.xacro" />
<xacro:include filename="$(find bbot_new_description)/urdf/bbot_new_camera.xacro" />
<!-- <xacro:include filename="$(find bbot_new_description)/urdf/bbot_new_depthcamera.xacro" /> -->
<xacro:include filename="$(find bbot_new_description)/urdf/bbot_new_lidar.xacro" />

<link name="base_footprint" />

<link name="base_link">
  <inertial>
    <origin xyz="-0.006057605134441126 -0.00018111500705384267 0.10888749093150545" rpy="0 0 0"/>
    <mass value="1.049122069689706"/>
    <inertia ixx="0.006186" iyy="0.006006" izz="0.00631" ixy="-0.0" iyz="0.0" ixz="-0.000632"/>
  </inertial>
  <visual>
    <origin xyz="0 0 0" rpy="0 0 0"/>
    <geometry>
      <mesh filename="file://$(find bbot_new_description)/meshes/base_link.stl" scale="0.001 0.001 0.001"/>
    </geometry>
    <material name="silver"/>
  </visual>
  <collision>
    <origin xyz="0 0 0" rpy="0 0 0"/>
    <geometry>
      <mesh filename="file://$(find bbot_new_description)/meshes/base_link.stl" scale="0.001 0.001 0.001"/>
    </geometry>
  </collision>
</link>

<link name="lidar">
  <inertial>
    <origin xyz="-3.6197078243972464e-07 -1.1500705524792785e-07 0.007500311251273456" rpy="0 0 0"/>
    <mass value="0.02686061718819272"/>
    <inertia ixx="3e-06" iyy="3e-06" izz="5e-06" ixy="-0.0" iyz="0.0" ixz="0.0"/>
  </inertial>
  <visual>
    <origin xyz="-0.000257 0.000181 -0.193407" rpy="0 0 0"/>
    <geometry>
      <mesh filename="file://$(find bbot_new_description)/meshes/lidar_1.stl" scale="0.001 0.001 0.001"/>
    </geometry>
    <material name="silver"/>
  </visual>
  <collision>
    <origin xyz="-0.000257 0.000181 -0.193407" rpy="0 0 0"/>
    <geometry>
      <mesh filename="file://$(find bbot_new_description)/meshes/lidar_1.stl" scale="0.001 0.001 0.001"/>
    </geometry>
  </collision>
</link>

<link name="camera">
  <inertial>
    <origin xyz="0.0009996380292177226 -1.150070553431208e-07 3.138589770024236e-07" rpy="0 0 0"/>
    <mass value="0.0017100000509619655"/>
    <inertia ixx="0.0" iyy="0.0" izz="0.0" ixy="-0.0" iyz="0.0" ixz="0.0"/>
  </inertial>
  <visual>
    <origin xyz="-0.102757 0.000181 -0.175407" rpy="0 0 0"/>
    <geometry>
      <mesh filename="file://$(find bbot_new_description)/meshes/camera_1.stl" scale="0.001 0.001 0.001"/>
    </geometry>
    <material name="silver"/>
  </visual>
  <collision>
    <origin xyz="-0.102757 0.000181 -0.175407" rpy="0 0 0"/>
    <geometry>
      <mesh filename="file://$(find bbot_new_description)/meshes/camera_1.stl" scale="0.001 0.001 0.001"/>
    </geometry>
  </collision>
</link>

<link name="camera_optical_link"/>

<link name="rightwheel">
  <inertial>
    <origin xyz="-3.6279034571623514e-07 -0.012500115007057472 3.1181752010306374e-07" rpy="0 0 0"/>
    <mass value="0.11821469543761899"/>
    <inertia ixx="3.7e-05" iyy="6.2e-05" izz="3.7e-05" ixy="-0.0" iyz="0.0" ixz="-0.0"/>
  </inertial>
  <visual>
    <origin xyz="0.054743 0.112681 -0.038407" rpy="0 0 0"/>
    <geometry>
      <mesh filename="file://$(find bbot_new_description)/meshes/rightwheel_1.stl" scale="0.001 0.001 0.001"/>
    </geometry>
    <material name="silver"/>
  </visual>
  <collision>
    <origin xyz="0.054743 0.112681 -0.038407" rpy="0 0 0"/>
    <geometry>
      <mesh filename="file://$(find bbot_new_description)/meshes/rightwheel_1.stl" scale="0.001 0.001 0.001"/>
    </geometry>
  </collision>
</link>

<link name="leftwheel">
  <inertial>
    <origin xyz="-3.627903472150362e-07 0.012499884992944452 3.118175187846739e-07" rpy="0 0 0"/>
    <mass value="0.11821469543761903"/>
    <inertia ixx="3.7e-05" iyy="6.2e-05" izz="3.7e-05" ixy="-0.0" iyz="-0.0" ixz="0.0"/>
  </inertial>
  <visual>
    <origin xyz="0.054743 -0.112319 -0.038407" rpy="0 0 0"/>
    <geometry>
      <mesh filename="file://$(find bbot_new_description)/meshes/leftwheel_1.stl" scale="0.001 0.001 0.001"/>
    </geometry>
    <material name="silver"/>
  </visual>
  <collision>
    <origin xyz="0.054743 -0.112319 -0.038407" rpy="0 0 0"/>
    <geometry>
      <mesh filename="file://$(find bbot_new_description)/meshes/leftwheel_1.stl" scale="0.001 0.001 0.001"/>
    </geometry>
  </collision>
</link>

<link name="caster_wheel_left" >
  <inertial>
    <origin xyz="0 0 0" rpy="0 0 0" />
    <mass value="0.49122069689706" />
    <inertia ixx="" iyy="" izz="" ixy="" iyz="" ixz=""/>
  </inertial>
  <visual>
    <origin xyz="0 0 0" rpy="0 0 0"/>
    <geometry>
      <sphere radius="0.02"/>
    </geometry>
    <material name="silver"/>
  </visual>
  <collision>
    <origin xyz="0 0 0" rpy="0 0 0"/>
    <geometry>
      <sphere radius="0.02"/>
    </geometry>
  </collision>

</link>

<link name="caster_wheel_right" >
  <!-- <inertial>
    <origin xyz="" rpy="" />
    <mass value="0.49122069689706" />
    <inertia ixx="" iyy="" izz="" ixy="" iyz="" ixz=""/>
  </inertial> -->
  <visual>
    <origin xyz="0 0 0" rpy="0 0 0"/>
    <geometry>
      <sphere radius="0.02"/>
    </geometry>
    <material name="silver"/>
  </visual>
  <collision>
    <origin xyz="0 0 0" rpy="0 0 0"/>
    <geometry>
      <sphere radius="0.02"/>
    </geometry>
  </collision>

</link>

<joint name="base_basefootprint_joint" type="fixed">
  <origin xyz="0 0 0" rpy="0 0 0"/>
  <parent link="base_link"/>
  <child link="base_footprint"/>
</joint>

<joint name="leftcaster_joint" type="fixed">
  <origin xyz="0.06 -0.06 0.02" ryz="0 0 0"/>
  <parent link="base_link" />
  <child link="caster_wheel_left" />
</joint>

<joint name="rightcaster_joint" type="fixed">
  <origin xyz="0.06 0.06 0.02" ryz="0 0 0"/>
  <parent link="base_link" />
  <child link="caster_wheel_right" />
</joint>

<joint name="base_lidar_joint" type="fixed">
  <origin xyz="0.000257 -0.000181 0.194407" rpy="0 0 0"/>
  <parent link="base_link"/>
  <child link="lidar"/>
</joint>

<joint name="base_camera_joint" type="fixed">
  <origin xyz="0.102757 -0.000181 0.175407" rpy="0 0 0"/>
  <parent link="base_link"/>
  <child link="camera"/>
</joint>

<joint name="camera_cameraoptical_joint" type="fixed">
  <parent link="camera"/>
  <child link="camera_optical_link"/>
  <origin xyz="0 0 0" rpy="${-pi/2} 0 ${-pi/2}" />
</joint>

<joint name="base_rightwheel_joint" type="continuous">
  <origin xyz="-0.054743 -0.112681 0.038407" rpy="0 0 0"/>
  <parent link="base_link"/>
  <child link="rightwheel"/>
  <axis xyz="-0.0 1.0 -0.0"/>
</joint>

<joint name="base_leftwheel_joint" type="continuous">
  <origin xyz="-0.054743 0.112319 0.038407" rpy="0 0 0"/>
  <parent link="base_link"/>
  <child link="leftwheel"/>
  <axis xyz="-0.0 1.0 -0.0"/>
</joint>

</robot>
