<?xml version="1.0" ?>
<robot name="bbot" xmlns:xacro="http://www.ros.org/wiki/xacro">

<xacro:include filename="$(find bbot_description)/urdf/materials.xacro" />
<xacro:include filename="$(find bbot_description)/urdf/bbot.trans" />
<xacro:include filename="$(find bbot_description)/urdf/bbot.gazebo" />
<xacro:include filename="$(find bbot_description)/urdf/camera1.xacro" />
<xacro:include filename="$(find bbot_description)/urdf/lidar1.xacro" />
<xacro:include filename="$(find bbot_description)/urdf/ros2_control.xacro" />


<link name="base_footprint"></link>

<link name="base_link">
  <inertial>
    <origin xyz="-0.006314243163658662 2.1121252064254716e-15 0.10298851522133046" rpy="0 0 0"/>
    <mass value="1.0491220696897063"/>
    <inertia ixx="0.006187" iyy="0.006007" izz="0.00631" ixy="-0.0" iyz="0.0" ixz="-0.000632"/>
  </inertial>
  <visual>
    <origin xyz="0 0 0" rpy="0 0 0"/>
    <geometry>
      <mesh filename="file://$(find bbot_description)/meshes/base_link.stl" scale="0.001 0.001 0.001"/>
    </geometry>
    <material name="white"/>
  </visual>
  <collision>
    <origin xyz="0 0 0" rpy="0 0 0"/>
    <geometry>
      <mesh filename="file://$(find bbot_description)/meshes/base_link.stl" scale="0.001 0.001 0.001"/>
    </geometry>
  </collision>
</link>

<link name="lidar">
  <inertial>
    <origin xyz="0.0 0.0 0.007500000000000034" rpy="0 0 0"/>
    <mass value="0.02686061718819272"/>
    <inertia ixx="3e-06" iyy="3e-06" izz="5e-06" ixy="0.0" iyz="0.0" ixz="-0.0"/>
  </inertial>
  <visual>
    <origin xyz="-0.0 -0.0 -0.1875" rpy="0 0 0"/>
    <geometry>
      <mesh filename="file://$(find bbot_description)/meshes/lidar_1.stl" scale="0.001 0.001 0.001"/>
    </geometry>
    <material name="red"/>
  </visual>
  <collision>
    <origin xyz="-0.0 -0.0 -0.1875" rpy="0 0 0"/>
    <geometry>
      <mesh filename="file://$(find bbot_description)/meshes/lidar_1.stl" scale="0.001 0.001 0.001"/>
    </geometry>
  </collision>
</link>

<link name="leftwheel">
  <inertial>
    <origin xyz="-8.195639167318802e-10 0.012500000000000025 5.66244127975235e-10" rpy="0 0 0"/>
    <mass value="0.11821469543761903"/>
    <inertia ixx="3.7e-05" iyy="6.2e-05" izz="3.7e-05" ixy="0.0" iyz="-0.0" ixz="0.0"/>
  </inertial>
  <visual>
    <origin xyz="0.055 -0.1125 -0.0325" rpy="0 0 0"/>
    <geometry>
      <mesh filename="file://$(find bbot_description)/meshes/leftwheel_1.stl" scale="0.001 0.001 0.001"/>
    </geometry>
    <material name="black"/>
  </visual>
  <collision>
    <origin xyz="0.055 -0.1125 -0.0325" rpy="0 0 0"/>
    <geometry>
      <mesh filename="file://$(find bbot_description)/meshes/leftwheel_1.stl" scale="0.001 0.001 0.001"/>
    </geometry>
  </collision>
</link>

<link name="rigthwheel">
  <inertial>
    <origin xyz="-8.195638681596229e-10 -0.01250000000000008 5.66244127975235e-10" rpy="0 0 0"/>
    <mass value="0.11821469543761906"/>
    <inertia ixx="3.7e-05" iyy="6.2e-05" izz="3.7e-05" ixy="0.0" iyz="0.0" ixz="0.0"/>
  </inertial>
  <visual>
    <origin xyz="0.055 0.1125 -0.0325" rpy="0 0 0"/>
    <geometry>
      <mesh filename="file://$(find bbot_description)/meshes/rigthwheel_1.stl" scale="0.001 0.001 0.001"/>
    </geometry>
    <material name="black"/>
  </visual>
  <collision>
    <origin xyz="0.055 0.1125 -0.0325" rpy="0 0 0"/>
    <geometry>
      <mesh filename="file://$(find bbot_description)/meshes/rigthwheel_1.stl" scale="0.001 0.001 0.001"/>
    </geometry>
  </collision>
</link>

<link name="camera">
  <inertial>
    <origin xyz="0.0010000000000000564 2.298161660974074e-17 2.6077032477811457e-09" rpy="0 0 0"/>
    <mass value="0.0017100000509619655"/>
    <inertia ixx="3.7e-07" iyy="6.2e-07" izz="3.7e-07" ixy="-0.0" iyz="0.0" ixz="0.0"/>
  </inertial>
  <visual>
    <origin xyz="-0.1025 -0.0 -0.175" rpy="0 0 0"/>
    <geometry>
      <mesh filename="file://$(find bbot_description)/meshes/camera_1.stl" scale="0.001 0.001 0.001"/>
    </geometry>
    <material name="red"/>
  </visual>
  <collision>
    <origin xyz="-0.1025 -0.0 -0.175" rpy="0 0 0"/>
    <geometry>
      <mesh filename="file://$(find bbot_description)/meshes/camera_1.stl" scale="0.001 0.001 0.001"/>
    </geometry>
  </collision>
</link>

<joint name="footprint_base_joint" type="fixed">
  <origin xyz="0.0 0.0 0.0" rpy="0 0 0"/>
  <parent link="base_footprint"/>
  <child link="base_link"/>
</joint>

<joint name="base_lidar_joint" type="fixed">
  <origin xyz="0.0 0.0 0.1875" rpy="0 0 0"/>
  <parent link="base_link"/>
  <child link="lidar"/>
</joint>

<joint name="base_leftwheel_joint" type="continuous">
  <origin xyz="-0.055 0.1125 0.0325" rpy="0 0 0"/>
  <parent link="base_link"/>
  <child link="leftwheel"/>
  <axis xyz="0.0 -1.0 0.0"/>
</joint>

<joint name="base_rightwheel_joint" type="continuous">
  <origin xyz="-0.055 -0.1125 0.0325" rpy="0 0 0"/>
  <parent link="base_link"/>
  <child link="rigthwheel"/>
  <axis xyz="0.0 -1.0 0.0"/>
</joint>

<joint name="base_camera_joint" type="fixed">
  <origin xyz="0.1025 0.0 0.175" rpy="0 0 0"/>
  <parent link="base_link"/>
  <child link="camera"/>
</joint>

</robot>
